2021/01/21 12:48:06 - check_connections_and_config - Using run configuration [Pentaho local]
2021/01/21 12:48:10 - load_plain - Using run configuration [Pentaho local]
2021/01/21 12:53:30 - load_link - Using run configuration [Pentaho local]
2021/01/21 12:53:38 - ti_grupo_investigacion.0 - ERROR (version 9.1.0.0-324, build 9.1.0.0-324 from 2020-09-07 05.09.05 by buildguy) : Unexpected error
2021/01/21 12:53:38 - ti_grupo_investigacion.0 - ERROR (version 9.1.0.0-324, build 9.1.0.0-324 from 2020-09-07 05.09.05 by buildguy) : org.pentaho.di.core.exception.KettleDatabaseException: 
2021/01/21 12:53:38 - ti_grupo_investigacion.0 - An error occurred executing SQL: 
2021/01/21 12:53:38 - ti_grupo_investigacion.0 - SELECT
  id
, version
, nombre
, idUniversidad
, idEjecucion
, fechaCreacion
, fechaModificacion
, operation
FROM GrupoInvestigacion


2021/01/21 12:53:38 - ti_grupo_investigacion.0 - (conn=4105) Unknown column 'idUniversidad' in 'field list'
2021/01/21 12:53:38 - ti_grupo_investigacion.0 - 
2021/01/21 12:53:38 - ti_grupo_investigacion.0 - 	at org.pentaho.di.core.database.Database.openQuery(Database.java:1772)
2021/01/21 12:53:38 - ti_grupo_investigacion.0 - 	at org.pentaho.di.trans.steps.tableinput.TableInput.doQuery(TableInput.java:236)
2021/01/21 12:53:38 - ti_grupo_investigacion.0 - 	at org.pentaho.di.trans.steps.tableinput.TableInput.processRow(TableInput.java:140)
2021/01/21 12:53:38 - ti_grupo_investigacion.0 - 	at org.pentaho.di.trans.step.RunThread.run(RunThread.java:62)
2021/01/21 12:53:38 - ti_grupo_investigacion.0 - 	at java.lang.Thread.run(Unknown Source)
2021/01/21 12:53:38 - ti_grupo_investigacion.0 - Caused by: java.sql.SQLSyntaxErrorException: (conn=4105) Unknown column 'idUniversidad' in 'field list'
2021/01/21 12:53:38 - ti_grupo_investigacion.0 - 	at org.mariadb.jdbc.internal.util.exceptions.ExceptionMapper.get(ExceptionMapper.java:243)
2021/01/21 12:53:38 - ti_grupo_investigacion.0 - 	at org.mariadb.jdbc.internal.util.exceptions.ExceptionMapper.getException(ExceptionMapper.java:164)
2021/01/21 12:53:38 - ti_grupo_investigacion.0 - 	at org.mariadb.jdbc.MariaDbStatement.executeExceptionEpilogue(MariaDbStatement.java:258)
2021/01/21 12:53:38 - ti_grupo_investigacion.0 - 	at org.mariadb.jdbc.MariaDbStatement.executeInternal(MariaDbStatement.java:349)
2021/01/21 12:53:38 - ti_grupo_investigacion.0 - 	at org.mariadb.jdbc.MariaDbStatement.executeQuery(MariaDbStatement.java:595)
2021/01/21 12:53:38 - ti_grupo_investigacion.0 - 	at org.pentaho.di.core.database.Database.openQuery(Database.java:1761)
2021/01/21 12:53:38 - ti_grupo_investigacion.0 - 	... 4 more
2021/01/21 12:53:38 - ti_grupo_investigacion.0 - Caused by: java.sql.SQLException: Unknown column 'idUniversidad' in 'field list'
2021/01/21 12:53:38 - ti_grupo_investigacion.0 - 	at org.mariadb.jdbc.internal.protocol.AbstractQueryProtocol.readErrorPacket(AbstractQueryProtocol.java:1598)
2021/01/21 12:53:38 - ti_grupo_investigacion.0 - 	at org.mariadb.jdbc.internal.protocol.AbstractQueryProtocol.readPacket(AbstractQueryProtocol.java:1460)
2021/01/21 12:53:38 - ti_grupo_investigacion.0 - 	at org.mariadb.jdbc.internal.protocol.AbstractQueryProtocol.getResult(AbstractQueryProtocol.java:1423)
2021/01/21 12:53:38 - ti_grupo_investigacion.0 - 	at org.mariadb.jdbc.internal.protocol.AbstractQueryProtocol.executeQuery(AbstractQueryProtocol.java:178)
2021/01/21 12:53:38 - ti_grupo_investigacion.0 - 	at org.mariadb.jdbc.MariaDbStatement.executeInternal(MariaDbStatement.java:343)
2021/01/21 12:53:38 - ti_grupo_investigacion.0 - 	... 6 more
2021/01/21 12:53:38 - 5.2.6_load_link_proyecto_internacional - ERROR (version 9.1.0.0-324, build 9.1.0.0-324 from 2020-09-07 05.09.05 by buildguy) : Errors detected!
2021/01/21 12:53:39 - 5.2.6_load_link_proyecto_internacional - ERROR (version 9.1.0.0-324, build 9.1.0.0-324 from 2020-09-07 05.09.05 by buildguy) : Errors detected!
2021/01/21 12:53:40 - abrt_entity_load_fail - ERROR (version 9.1.0.0-324, build 9.1.0.0-324 from 2020-09-07 05.09.05 by buildguy) : ERROR: load PROYECTO_INT_LINK entity fail
2021/01/21 12:53:41 - load_finalize_failed - Using run configuration [Pentaho local]
2021/01/21 12:53:41 - 9.0.finalize_failed - ERROR (version 9.1.0.0-324, build 9.1.0.0-324 from 2020-09-07 05.09.05 by buildguy) : Unable to run job j_finalize_failed. The 9.0.finalize_failed has an error. The transformation path C:/Users/igancedo/Desktop/PDI/ASIO-UM/ETL final/project/9.end/9.0.finalize_failed.ktr is invalid, and will not run successfully.
2021/01/21 12:53:41 - 9.0.finalize_failed - ERROR (version 9.1.0.0-324, build 9.1.0.0-324 from 2020-09-07 05.09.05 by buildguy) : org.pentaho.di.core.exception.KettleXMLException: 
2021/01/21 12:53:41 - 9.0.finalize_failed - The transformation path C:/Users/igancedo/Desktop/PDI/ASIO-UM/ETL final/project/9.end/9.0.finalize_failed.ktr is invalid, and will not run successfully.
2021/01/21 12:53:41 - 9.0.finalize_failed - 
2021/01/21 12:53:41 - 9.0.finalize_failed - 	at org.pentaho.di.trans.TransMeta.<init>(TransMeta.java:2788)
2021/01/21 12:53:41 - 9.0.finalize_failed - 	at org.pentaho.di.trans.TransMeta.<init>(TransMeta.java:2750)
2021/01/21 12:53:41 - 9.0.finalize_failed - 	at org.pentaho.di.trans.TransMeta.<init>(TransMeta.java:2727)
2021/01/21 12:53:41 - 9.0.finalize_failed - 	at org.pentaho.di.trans.TransMeta.<init>(TransMeta.java:2707)
2021/01/21 12:53:41 - 9.0.finalize_failed - 	at org.pentaho.di.repository.filerep.KettleFileRepository.loadTransformation(KettleFileRepository.java:1110)
2021/01/21 12:53:41 - 9.0.finalize_failed - 	at org.pentaho.di.job.entries.trans.JobEntryTrans.getTransMetaFromRepository(JobEntryTrans.java:1303)
2021/01/21 12:53:41 - 9.0.finalize_failed - 	at org.pentaho.di.job.entries.trans.JobEntryTrans.getTransMeta(JobEntryTrans.java:1338)
2021/01/21 12:53:41 - 9.0.finalize_failed - 	at org.pentaho.di.job.entries.trans.JobEntryTrans.execute(JobEntryTrans.java:716)
2021/01/21 12:53:41 - 9.0.finalize_failed - 	at org.pentaho.di.job.Job.execute(Job.java:682)
2021/01/21 12:53:41 - 9.0.finalize_failed - 	at org.pentaho.di.job.Job.execute(Job.java:823)
2021/01/21 12:53:41 - 9.0.finalize_failed - 	at org.pentaho.di.job.Job.execute(Job.java:567)
2021/01/21 12:53:41 - 9.0.finalize_failed - 	at org.pentaho.di.job.entries.job.JobEntryJobRunner.run(JobEntryJobRunner.java:69)
2021/01/21 12:53:41 - 9.0.finalize_failed - 	at java.lang.Thread.run(Unknown Source)
2021/01/21 12:59:48 - load_link_proyecto - Using run configuration [Pentaho local]
2021/01/21 12:59:48 - load_link_proyecto - Running transformation using the Kettle execution engine
2021/01/21 12:59:53 - load_link_proyecto_internacional - Using run configuration [Pentaho local]
2021/01/21 12:59:53 - load_link_proyecto_internacional - Running transformation using the Kettle execution engine
2021/01/21 12:59:53 - ti_grupo_investigacion.0 - ERROR (version 9.1.0.0-324, build 9.1.0.0-324 from 2020-09-07 05.09.05 by buildguy) : Unexpected error
2021/01/21 12:59:53 - ti_grupo_investigacion.0 - ERROR (version 9.1.0.0-324, build 9.1.0.0-324 from 2020-09-07 05.09.05 by buildguy) : org.pentaho.di.core.exception.KettleDatabaseException: 
2021/01/21 12:59:53 - ti_grupo_investigacion.0 - An error occurred executing SQL: 
2021/01/21 12:59:53 - ti_grupo_investigacion.0 - SELECT
  id
, version
, nombre
, idUniversidad
, idEjecucion
, fechaCreacion
, fechaModificacion
, operation
FROM GrupoInvestigacion


2021/01/21 12:59:53 - ti_grupo_investigacion.0 - (conn=4120) Unknown column 'idUniversidad' in 'field list'
2021/01/21 12:59:53 - ti_grupo_investigacion.0 - 
2021/01/21 12:59:53 - ti_grupo_investigacion.0 - 	at org.pentaho.di.core.database.Database.openQuery(Database.java:1772)
2021/01/21 12:59:53 - ti_grupo_investigacion.0 - 	at org.pentaho.di.trans.steps.tableinput.TableInput.doQuery(TableInput.java:236)
2021/01/21 12:59:53 - ti_grupo_investigacion.0 - 	at org.pentaho.di.trans.steps.tableinput.TableInput.processRow(TableInput.java:140)
2021/01/21 12:59:53 - ti_grupo_investigacion.0 - 	at org.pentaho.di.trans.step.RunThread.run(RunThread.java:62)
2021/01/21 12:59:53 - ti_grupo_investigacion.0 - 	at java.lang.Thread.run(Unknown Source)
2021/01/21 12:59:53 - ti_grupo_investigacion.0 - Caused by: java.sql.SQLSyntaxErrorException: (conn=4120) Unknown column 'idUniversidad' in 'field list'
2021/01/21 12:59:53 - ti_grupo_investigacion.0 - 	at org.mariadb.jdbc.internal.util.exceptions.ExceptionMapper.get(ExceptionMapper.java:243)
2021/01/21 12:59:53 - ti_grupo_investigacion.0 - 	at org.mariadb.jdbc.internal.util.exceptions.ExceptionMapper.getException(ExceptionMapper.java:164)
2021/01/21 12:59:53 - ti_grupo_investigacion.0 - 	at org.mariadb.jdbc.MariaDbStatement.executeExceptionEpilogue(MariaDbStatement.java:258)
2021/01/21 12:59:53 - ti_grupo_investigacion.0 - 	at org.mariadb.jdbc.MariaDbStatement.executeInternal(MariaDbStatement.java:349)
2021/01/21 12:59:53 - ti_grupo_investigacion.0 - 	at org.mariadb.jdbc.MariaDbStatement.executeQuery(MariaDbStatement.java:595)
2021/01/21 12:59:53 - ti_grupo_investigacion.0 - 	at org.pentaho.di.core.database.Database.openQuery(Database.java:1761)
2021/01/21 12:59:53 - ti_grupo_investigacion.0 - 	... 4 more
2021/01/21 12:59:53 - ti_grupo_investigacion.0 - Caused by: java.sql.SQLException: Unknown column 'idUniversidad' in 'field list'
2021/01/21 12:59:53 - ti_grupo_investigacion.0 - 	at org.mariadb.jdbc.internal.protocol.AbstractQueryProtocol.readErrorPacket(AbstractQueryProtocol.java:1598)
2021/01/21 12:59:53 - ti_grupo_investigacion.0 - 	at org.mariadb.jdbc.internal.protocol.AbstractQueryProtocol.readPacket(AbstractQueryProtocol.java:1460)
2021/01/21 12:59:53 - ti_grupo_investigacion.0 - 	at org.mariadb.jdbc.internal.protocol.AbstractQueryProtocol.getResult(AbstractQueryProtocol.java:1423)
2021/01/21 12:59:53 - ti_grupo_investigacion.0 - 	at org.mariadb.jdbc.internal.protocol.AbstractQueryProtocol.executeQuery(AbstractQueryProtocol.java:178)
2021/01/21 12:59:53 - ti_grupo_investigacion.0 - 	at org.mariadb.jdbc.MariaDbStatement.executeInternal(MariaDbStatement.java:343)
2021/01/21 12:59:53 - ti_grupo_investigacion.0 - 	... 6 more
2021/01/21 12:59:53 - 5.2.6_load_link_proyecto_internacional - ERROR (version 9.1.0.0-324, build 9.1.0.0-324 from 2020-09-07 05.09.05 by buildguy) : Errors detected!
2021/01/21 12:59:54 - 5.2.6_load_link_proyecto_internacional - ERROR (version 9.1.0.0-324, build 9.1.0.0-324 from 2020-09-07 05.09.05 by buildguy) : Errors detected!
2021/01/21 12:59:54 - control_error - Using run configuration [Pentaho local]
2021/01/21 12:59:54 - control_error - Running transformation using the Kettle execution engine
2021/01/21 13:00:14 - load_link_proyecto - Using run configuration [Pentaho local]
2021/01/21 13:00:14 - load_link_proyecto - Running transformation using the Kettle execution engine
2021/01/21 13:00:19 - load_link_proyecto_internacional - Using run configuration [Pentaho local]
2021/01/21 13:00:19 - load_link_proyecto_internacional - Running transformation using the Kettle execution engine
2021/01/21 13:00:19 - ti_grupo_investigacion.0 - ERROR (version 9.1.0.0-324, build 9.1.0.0-324 from 2020-09-07 05.09.05 by buildguy) : Unexpected error
2021/01/21 13:00:19 - ti_grupo_investigacion.0 - ERROR (version 9.1.0.0-324, build 9.1.0.0-324 from 2020-09-07 05.09.05 by buildguy) : org.pentaho.di.core.exception.KettleDatabaseException: 
2021/01/21 13:00:19 - ti_grupo_investigacion.0 - An error occurred executing SQL: 
2021/01/21 13:00:19 - ti_grupo_investigacion.0 - SELECT
  id
, version
, nombre
, idUniversidad
, idEjecucion
, fechaCreacion
, fechaModificacion
, operation
FROM GrupoInvestigacion


2021/01/21 13:00:19 - ti_grupo_investigacion.0 - (conn=4137) Unknown column 'idUniversidad' in 'field list'
2021/01/21 13:00:19 - ti_grupo_investigacion.0 - 
2021/01/21 13:00:19 - ti_grupo_investigacion.0 - 	at org.pentaho.di.core.database.Database.openQuery(Database.java:1772)
2021/01/21 13:00:19 - ti_grupo_investigacion.0 - 	at org.pentaho.di.trans.steps.tableinput.TableInput.doQuery(TableInput.java:236)
2021/01/21 13:00:19 - ti_grupo_investigacion.0 - 	at org.pentaho.di.trans.steps.tableinput.TableInput.processRow(TableInput.java:140)
2021/01/21 13:00:19 - ti_grupo_investigacion.0 - 	at org.pentaho.di.trans.step.RunThread.run(RunThread.java:62)
2021/01/21 13:00:19 - ti_grupo_investigacion.0 - 	at java.lang.Thread.run(Unknown Source)
2021/01/21 13:00:19 - ti_grupo_investigacion.0 - Caused by: java.sql.SQLSyntaxErrorException: (conn=4137) Unknown column 'idUniversidad' in 'field list'
2021/01/21 13:00:19 - ti_grupo_investigacion.0 - 	at org.mariadb.jdbc.internal.util.exceptions.ExceptionMapper.get(ExceptionMapper.java:243)
2021/01/21 13:00:19 - ti_grupo_investigacion.0 - 	at org.mariadb.jdbc.internal.util.exceptions.ExceptionMapper.getException(ExceptionMapper.java:164)
2021/01/21 13:00:19 - ti_grupo_investigacion.0 - 	at org.mariadb.jdbc.MariaDbStatement.executeExceptionEpilogue(MariaDbStatement.java:258)
2021/01/21 13:00:19 - ti_grupo_investigacion.0 - 	at org.mariadb.jdbc.MariaDbStatement.executeInternal(MariaDbStatement.java:349)
2021/01/21 13:00:19 - ti_grupo_investigacion.0 - 	at org.mariadb.jdbc.MariaDbStatement.executeQuery(MariaDbStatement.java:595)
2021/01/21 13:00:19 - ti_grupo_investigacion.0 - 	at org.pentaho.di.core.database.Database.openQuery(Database.java:1761)
2021/01/21 13:00:19 - ti_grupo_investigacion.0 - 	... 4 more
2021/01/21 13:00:19 - ti_grupo_investigacion.0 - Caused by: java.sql.SQLException: Unknown column 'idUniversidad' in 'field list'
2021/01/21 13:00:19 - ti_grupo_investigacion.0 - 	at org.mariadb.jdbc.internal.protocol.AbstractQueryProtocol.readErrorPacket(AbstractQueryProtocol.java:1598)
2021/01/21 13:00:19 - ti_grupo_investigacion.0 - 	at org.mariadb.jdbc.internal.protocol.AbstractQueryProtocol.readPacket(AbstractQueryProtocol.java:1460)
2021/01/21 13:00:19 - ti_grupo_investigacion.0 - 	at org.mariadb.jdbc.internal.protocol.AbstractQueryProtocol.getResult(AbstractQueryProtocol.java:1423)
2021/01/21 13:00:19 - ti_grupo_investigacion.0 - 	at org.mariadb.jdbc.internal.protocol.AbstractQueryProtocol.executeQuery(AbstractQueryProtocol.java:178)
2021/01/21 13:00:19 - ti_grupo_investigacion.0 - 	at org.mariadb.jdbc.MariaDbStatement.executeInternal(MariaDbStatement.java:343)
2021/01/21 13:00:19 - ti_grupo_investigacion.0 - 	... 6 more
2021/01/21 13:00:19 - 5.2.6_load_link_proyecto_internacional - ERROR (version 9.1.0.0-324, build 9.1.0.0-324 from 2020-09-07 05.09.05 by buildguy) : Errors detected!
2021/01/21 13:00:20 - 5.2.6_load_link_proyecto_internacional - ERROR (version 9.1.0.0-324, build 9.1.0.0-324 from 2020-09-07 05.09.05 by buildguy) : Errors detected!
2021/01/21 13:00:20 - control_error - Using run configuration [Pentaho local]
2021/01/21 13:00:20 - control_error - Running transformation using the Kettle execution engine
2021/01/21 13:03:01 - load_link_proyecto - Using run configuration [Pentaho local]
2021/01/21 13:03:01 - load_link_proyecto - Running transformation using the Kettle execution engine
2021/01/21 13:03:06 - load_link_proyecto_internacional - Using run configuration [Pentaho local]
2021/01/21 13:03:06 - load_link_proyecto_internacional - Running transformation using the Kettle execution engine
2021/01/21 13:03:11 - load_link_patente - Using run configuration [Pentaho local]
2021/01/21 13:03:11 - load_link_patente - Running transformation using the Kettle execution engine
2021/01/21 13:03:15 - load_link_articulo - Using run configuration [Pentaho local]
2021/01/21 13:03:15 - load_link_articulo - Running transformation using the Kettle execution engine
2021/01/21 13:03:19 - load_link_libro - Using run configuration [Pentaho local]
2021/01/21 13:03:19 - load_link_libro - Running transformation using the Kettle execution engine
2021/01/21 13:03:23 - load_link_tesis_externa - Using run configuration [Pentaho local]
2021/01/21 13:03:23 - load_link_tesis_externa - Running transformation using the Kettle execution engine
2021/01/21 13:03:27 - load_link_tesina_externa - Using run configuration [Pentaho local]
2021/01/21 13:03:27 - load_link_tesina_externa - Running transformation using the Kettle execution engine
2021/01/21 13:03:31 - load_link_dossier - Using run configuration [Pentaho local]
2021/01/21 13:03:31 - load_link_dossier - Running transformation using the Kettle execution engine
2021/01/21 13:03:35 - load_link_grupo_investigacion - Using run configuration [Pentaho local]
2021/01/21 13:03:35 - load_link_grupo_investigacion - Running transformation using the Kettle execution engine
2021/01/21 13:03:35 - ti_grupo_investigacion.0 - ERROR (version 9.1.0.0-324, build 9.1.0.0-324 from 2020-09-07 05.09.05 by buildguy) : Unexpected error
2021/01/21 13:03:35 - ti_grupo_investigacion.0 - ERROR (version 9.1.0.0-324, build 9.1.0.0-324 from 2020-09-07 05.09.05 by buildguy) : org.pentaho.di.core.exception.KettleDatabaseException: 
2021/01/21 13:03:35 - ti_grupo_investigacion.0 - An error occurred executing SQL: 
2021/01/21 13:03:35 - ti_grupo_investigacion.0 - SELECT
  id
, version
, nombre
, idUniversidad
, idEjecucion
, fechaCreacion
, fechaModificacion
, operation
FROM GrupoInvestigacion
where version = 39


2021/01/21 13:03:35 - ti_grupo_investigacion.0 - (conn=4185) Unknown column 'idUniversidad' in 'field list'
2021/01/21 13:03:35 - ti_grupo_investigacion.0 - 
2021/01/21 13:03:35 - ti_grupo_investigacion.0 - 	at org.pentaho.di.core.database.Database.openQuery(Database.java:1772)
2021/01/21 13:03:35 - ti_grupo_investigacion.0 - 	at org.pentaho.di.trans.steps.tableinput.TableInput.doQuery(TableInput.java:236)
2021/01/21 13:03:35 - ti_grupo_investigacion.0 - 	at org.pentaho.di.trans.steps.tableinput.TableInput.processRow(TableInput.java:140)
2021/01/21 13:03:35 - ti_grupo_investigacion.0 - 	at org.pentaho.di.trans.step.RunThread.run(RunThread.java:62)
2021/01/21 13:03:35 - ti_grupo_investigacion.0 - 	at java.lang.Thread.run(Unknown Source)
2021/01/21 13:03:35 - ti_grupo_investigacion.0 - Caused by: java.sql.SQLSyntaxErrorException: (conn=4185) Unknown column 'idUniversidad' in 'field list'
2021/01/21 13:03:35 - ti_grupo_investigacion.0 - 	at org.mariadb.jdbc.internal.util.exceptions.ExceptionMapper.get(ExceptionMapper.java:243)
2021/01/21 13:03:35 - ti_grupo_investigacion.0 - 	at org.mariadb.jdbc.internal.util.exceptions.ExceptionMapper.getException(ExceptionMapper.java:164)
2021/01/21 13:03:35 - ti_grupo_investigacion.0 - 	at org.mariadb.jdbc.MariaDbStatement.executeExceptionEpilogue(MariaDbStatement.java:258)
2021/01/21 13:03:35 - ti_grupo_investigacion.0 - 	at org.mariadb.jdbc.MariaDbStatement.executeInternal(MariaDbStatement.java:349)
2021/01/21 13:03:35 - ti_grupo_investigacion.0 - 	at org.mariadb.jdbc.MariaDbStatement.executeQuery(MariaDbStatement.java:595)
2021/01/21 13:03:35 - ti_grupo_investigacion.0 - 	at org.pentaho.di.core.database.Database.openQuery(Database.java:1761)
2021/01/21 13:03:35 - ti_grupo_investigacion.0 - 	... 4 more
2021/01/21 13:03:35 - ti_grupo_investigacion.0 - Caused by: java.sql.SQLException: Unknown column 'idUniversidad' in 'field list'
2021/01/21 13:03:35 - ti_grupo_investigacion.0 - 	at org.mariadb.jdbc.internal.protocol.AbstractQueryProtocol.readErrorPacket(AbstractQueryProtocol.java:1598)
2021/01/21 13:03:35 - ti_grupo_investigacion.0 - 	at org.mariadb.jdbc.internal.protocol.AbstractQueryProtocol.readPacket(AbstractQueryProtocol.java:1460)
2021/01/21 13:03:35 - ti_grupo_investigacion.0 - 	at org.mariadb.jdbc.internal.protocol.AbstractQueryProtocol.getResult(AbstractQueryProtocol.java:1423)
2021/01/21 13:03:35 - ti_grupo_investigacion.0 - 	at org.mariadb.jdbc.internal.protocol.AbstractQueryProtocol.executeQuery(AbstractQueryProtocol.java:178)
2021/01/21 13:03:35 - ti_grupo_investigacion.0 - 	at org.mariadb.jdbc.MariaDbStatement.executeInternal(MariaDbStatement.java:343)
2021/01/21 13:03:35 - ti_grupo_investigacion.0 - 	... 6 more
2021/01/21 13:03:35 - 5.2.3_load_link_grupo_investigacion - ERROR (version 9.1.0.0-324, build 9.1.0.0-324 from 2020-09-07 05.09.05 by buildguy) : Errors detected!
2021/01/21 13:03:35 - 5.2.3_load_link_grupo_investigacion - ERROR (version 9.1.0.0-324, build 9.1.0.0-324 from 2020-09-07 05.09.05 by buildguy) : Errors detected!
2021/01/21 13:03:36 - control_error - Using run configuration [Pentaho local]
2021/01/21 13:03:36 - control_error - Running transformation using the Kettle execution engine
2021/01/21 13:04:22 - load_link_proyecto - Using run configuration [Pentaho local]
2021/01/21 13:04:22 - load_link_proyecto - Running transformation using the Kettle execution engine
2021/01/21 13:04:27 - load_link_proyecto_internacional - Using run configuration [Pentaho local]
2021/01/21 13:04:27 - load_link_proyecto_internacional - Running transformation using the Kettle execution engine
2021/01/21 13:04:32 - load_link_patente - Using run configuration [Pentaho local]
2021/01/21 13:04:32 - load_link_patente - Running transformation using the Kettle execution engine
2021/01/21 13:04:36 - load_link_articulo - Using run configuration [Pentaho local]
2021/01/21 13:04:36 - load_link_articulo - Running transformation using the Kettle execution engine
2021/01/21 13:04:40 - load_link_libro - Using run configuration [Pentaho local]
2021/01/21 13:04:40 - load_link_libro - Running transformation using the Kettle execution engine
2021/01/21 13:04:44 - load_link_tesis_externa - Using run configuration [Pentaho local]
2021/01/21 13:04:44 - load_link_tesis_externa - Running transformation using the Kettle execution engine
2021/01/21 13:04:48 - load_link_tesina_externa - Using run configuration [Pentaho local]
2021/01/21 13:04:48 - load_link_tesina_externa - Running transformation using the Kettle execution engine
2021/01/21 13:04:53 - load_link_dossier - Using run configuration [Pentaho local]
2021/01/21 13:04:53 - load_link_dossier - Running transformation using the Kettle execution engine
2021/01/21 13:04:57 - load_link_grupo_investigacion - Using run configuration [Pentaho local]
2021/01/21 13:04:57 - load_link_grupo_investigacion - Running transformation using the Kettle execution engine
2021/01/21 13:05:01 - load_link_conference - Using run configuration [Pentaho local]
2021/01/21 13:05:01 - load_link_conference - Running transformation using the Kettle execution engine
2021/01/21 13:05:05 - load_link_exhibit - Using run configuration [Pentaho local]
2021/01/21 13:05:05 - load_link_exhibit - Running transformation using the Kettle execution engine
